#VRML_SIM R2019a utf8
WorldInfo {
}
Viewpoint {
  orientation -0.30625432991735113 -0.8750430524220401 -0.37484388992591716 1.9163999601383992
  position -4.153450095529063 4.149911538449491 -0.7790602935030333
}
TexturedBackground {
}
TexturedBackgroundLight {
}
Floor {
}
DEF OMNI_WHEELS Robot {
  translation 0.00021645852019284246 0.05698018407601391 -0.0002050255703809889
  children [
    DEF SOLID1 Solid {
      children [
        DEF WHEEL1 HingeJoint {
          jointParameters HingeJointParameters {
            position 16.38303994072588
            axis 0 0 1
            anchor 0 0 0.1
          }
          device [
            PositionSensor {
              name "encoder_left"
            }
            RotationalMotor {
              name "wheel1"
              maxVelocity 52.35
              maxTorque 0.49
            }
          ]
          endPoint Solid {
            translation 0 0 0.1
            rotation 0 0 1 3.8166693263667066
            children [
              DEF sr1 HingeJoint {
                jointParameters HingeJointParameters {
                  position -13.884928982794687
                  anchor 0 0.05 0.02
                }
                endPoint Solid {
                  translation 0 0.05 0.02
                  rotation -1 0 0 1.3185583684355138
                  children [
                    DEF r1 Transform {
                      rotation 0 0 1 1.5708
                      children [
                        DEF SMALL_WHEEL_SHAPE Shape {
                          appearance PBRAppearance {
                            baseColor 1 0.752941 0.796078
                            roughness 1
                            metalness 0
                          }
                          geometry Cylinder {
                            height 0.02
                            radius 0.01
                          }
                        }
                      ]
                    }
                  ]
                  name "sr1"
                  boundingObject USE r1
                  physics Physics {
                    density -1
                    mass 0.1
                  }
                }
              }
              DEF sr2 HingeJoint {
                jointParameters HingeJointParameters {
                  position -11.027166558212798
                  axis 0.707107 0.707107 0
                  anchor -0.03535 0.03535 0.02
                }
                endPoint Solid {
                  translation -0.03535 0.03535 0.02
                  rotation 0.7071067811865476 0.7071067811865476 0 1.539204056146375
                  children [
                    DEF r2 Transform {
                      rotation 0 0 1 2.27
                      children [
                        USE SMALL_WHEEL_SHAPE
                      ]
                    }
                  ]
                  name "sr2"
                  boundingObject USE r2
                  physics Physics {
                    density -1
                    mass 0.1
                  }
                }
              }
              DEF sr3 HingeJoint {
                jointParameters HingeJointParameters {
                  position 6.411208361599861
                  anchor 0 -0.05 0.02
                }
                endPoint Solid {
                  translation 0 -0.05 0.02
                  rotation -1 0 0 6.15516225275931
                  children [
                    DEF r3 Transform {
                      rotation 0 0 1 1.5708
                      children [
                        USE SMALL_WHEEL_SHAPE
                      ]
                    }
                  ]
                  name "sr3"
                  boundingObject USE r3
                  physics Physics {
                    density -1
                    mass 0.1
                  }
                }
              }
              DEF sr4 HingeJoint {
                jointParameters HingeJointParameters {
                  position 6.233294656230071
                  axis 0.707107 0.707107 0
                  anchor 0.03535 -0.03535 0.02
                }
                endPoint Solid {
                  translation 0.03535 -0.03535 0.02
                  rotation 0.7071067811865476 0.7071067811865476 0 6.2332946562300755
                  children [
                    DEF r4 Transform {
                      rotation 0 0 1 2.27
                      children [
                        USE SMALL_WHEEL_SHAPE
                      ]
                    }
                  ]
                  name "sr4"
                  boundingObject USE r4
                  physics Physics {
                    density -1
                    mass 0.1
                  }
                }
              }
              DEF sr5 HingeJoint {
                jointParameters HingeJointParameters {
                  position -14.436553386329228
                  axis 0 1 0
                  anchor -0.05 0 0.02
                }
                endPoint Solid {
                  translation -0.05 0 0.02
                  rotation 0 -1 0 1.8701827719700552
                  children [
                    DEF r5 Transform {
                      children [
                        USE SMALL_WHEEL_SHAPE
                      ]
                    }
                  ]
                  name "sr5"
                  boundingObject USE r5
                  physics Physics {
                    density -1
                    mass 0.1
                  }
                }
              }
              DEF sr6 HingeJoint {
                jointParameters HingeJointParameters {
                  position 10.513827300227744
                  axis 0 1 0
                  anchor 0.05 0 0.02
                }
                endPoint Solid {
                  translation 0.05 0 0.02
                  rotation 0 -1 0 2.052543314131429
                  children [
                    DEF r6 Transform {
                      children [
                        USE SMALL_WHEEL_SHAPE
                      ]
                    }
                  ]
                  name "sr6"
                  boundingObject USE r6
                  physics Physics {
                    density -1
                    mass 0.1
                  }
                }
              }
              DEF sr7 HingeJoint {
                jointParameters HingeJointParameters {
                  position -7.703387093195366
                  axis -0.707107 0.707107 0
                  anchor -0.03535 -0.03535 0.02
                }
                endPoint Solid {
                  translation -0.03535 -0.03535 0.02
                  rotation -0.7071067811865475 0.7071067811865475 0 4.862983521163807
                  children [
                    DEF r7 Transform {
                      rotation 0 0 1 0.76
                      children [
                        USE SMALL_WHEEL_SHAPE
                      ]
                    }
                  ]
                  name "sr7"
                  boundingObject USE r7
                  physics Physics {
                    density -1
                    mass 0.1
                  }
                }
              }
              DEF sr8 HingeJoint {
                jointParameters HingeJointParameters {
                  position 11.105835859982275
                  axis -0.707107 0.707107 0
                  anchor 0.03535 0.03535 0.02
                }
                endPoint Solid {
                  translation 0.03535 0.03535 0.02
                  rotation 0.7071067811865476 -0.7071067811865476 0 1.4605347543768983
                  children [
                    DEF r8 Transform {
                      rotation 0 0 1 0.76
                      children [
                        USE SMALL_WHEEL_SHAPE
                      ]
                    }
                  ]
                  name "sr8"
                  boundingObject USE r8
                  physics Physics {
                    density -1
                    mass 0.1
                  }
                }
              }
              DEF WHEEL_TRANS Transform {
                translation 0 0 0.02
                rotation 1 0 0 1.5708
                children [
                  DEF WHEEL_SHAPE Shape {
                    appearance PBRAppearance {
                      baseColor 0.678431 0.847059 0.901961
                      roughness 1
                      metalness 0
                    }
                    geometry Cylinder {
                      height 0.02
                      radius 0.05
                      subdivision 20
                    }
                  }
                ]
              }
            ]
            boundingObject Transform {
              translation 0 0 0.02
              rotation 1 0 0 1.5708
              children [
                DEF wheel1 Shape {
                  appearance PBRAppearance {
                    baseColor 0.8 0.8 0.8
                    transparency 0.12999999523162842
                    roughness 1
                    metalness 0
                    emissiveColor 0 1 0
                  }
                  geometry Cylinder {
                    height 0.02
                    radius 0.05
                  }
                }
              ]
            }
            physics Physics {
            }
          }
        }
      ]
      name "wheel 1"
      boundingObject DEF DUMMY Sphere {
        radius 0.01
      }
      physics Physics {
      }
    }
    DEF SOLID2 Solid {
      rotation 0 1 0 2.09
      children [
        DEF WHEEL2 HingeJoint {
          jointParameters HingeJointParameters {
            position 23.806934437421134
            axis 0 0 1
            anchor 0 0 0.1
          }
          device [
            RotationalMotor {
              name "wheel2"
              maxVelocity 52.35
              maxTorque 0.49
            }
          ]
          endPoint Solid {
            translation 0 0 0.1
            rotation 0 0 -1 1.3234009812972525
            children [
              DEF sr1 HingeJoint {
                jointParameters HingeJointParameters {
                  position -139.696623853763
                  anchor 0 0.05 0.02
                }
                endPoint Solid {
                  translation 0 0.05 0.02
                  rotation -1 0 0 1.4665470958120839
                  children [
                    USE r1
                  ]
                  name "sr1"
                  boundingObject USE r1
                  physics Physics {
                    density -1
                    mass 0.1
                  }
                }
              }
              DEF sr2 HingeJoint {
                jointParameters HingeJointParameters {
                  position -363.90957542629286
                  axis 0.707107 0.707107 0
                  anchor -0.03535 0.03535 0.02
                }
                endPoint Solid {
                  translation -0.03535 0.03535 0.02
                  rotation 0.7071067811865476 0.7071067811865476 0 0.5151723901231546
                  children [
                    USE r2
                  ]
                  name "sr2"
                  boundingObject USE r2
                  physics Physics {
                    density -1
                    mass 0.1
                  }
                }
              }
              DEF sr3 HingeJoint {
                jointParameters HingeJointParameters {
                  position -121.0424208686887
                  anchor 0 -0.05 0.02
                }
                endPoint Solid {
                  translation 0 -0.05 0.02
                  rotation 1 0 0 4.621285274903035
                  children [
                    USE r3
                  ]
                  name "sr3"
                  boundingObject USE r3
                  physics Physics {
                    density -1
                    mass 0.1
                  }
                }
              }
              DEF sr4 HingeJoint {
                jointParameters HingeJointParameters {
                  position -283.04394902183424
                  axis 0.707107 0.707107 0
                  anchor 0.03535 -0.03535 0.02
                }
                endPoint Solid {
                  translation 0.03535 -0.03535 0.02
                  rotation 0.7071067811865476 0.7071067811865476 0 5.982575108426741
                  children [
                    USE r4
                  ]
                  name "sr4"
                  boundingObject USE r4
                  physics Physics {
                    density -1
                    mass 0.1
                  }
                }
              }
              DEF sr5 HingeJoint {
                jointParameters HingeJointParameters {
                  position -412.8470963300515
                  axis 0 1 0
                  anchor -0.05 0 0.02
                }
                endPoint Solid {
                  translation -0.05 0 0.02
                  rotation 0 1 0 1.843133943801208
                  children [
                    USE r5
                  ]
                  name "sr5"
                  boundingObject USE r5
                  physics Physics {
                    density -1
                    mass 0.1
                  }
                }
              }
              DEF sr6 HingeJoint {
                jointParameters HingeJointParameters {
                  position -254.6596833733918
                  axis 0 1 0
                  anchor 0.05 0 0.02
                }
                endPoint Solid {
                  translation 0.05 0 0.02
                  rotation 0 -1 0 3.3322710862083413
                  children [
                    USE r6
                  ]
                  name "sr6"
                  boundingObject USE r6
                  physics Physics {
                    density -1
                    mass 0.1
                  }
                }
              }
              DEF sr7 HingeJoint {
                jointParameters HingeJointParameters {
                  position -420.46746511546485
                  axis -0.707107 0.707107 0
                  anchor -0.03535 -0.03535 0.02
                }
                endPoint Solid {
                  translation -0.03535 -0.03535 0.02
                  rotation 0.7071067811865476 -0.7071067811865476 0 5.77723484161214
                  children [
                    USE r7
                  ]
                  name "sr7"
                  boundingObject USE r7
                  physics Physics {
                    density -1
                    mass 0.1
                  }
                }
              }
              DEF sr8 HingeJoint {
                jointParameters HingeJointParameters {
                  position -237.64852667852352
                  axis -0.707107 0.707107 0
                  anchor 0.03535 0.03535 0.02
                }
                endPoint Solid {
                  translation 0.03535 0.03535 0.02
                  rotation -0.7071067811865476 0.7071067811865476 0 1.1125149943007622
                  children [
                    USE r8
                  ]
                  name "sr8"
                  boundingObject USE r8
                  physics Physics {
                    density -1
                    mass 0.1
                  }
                }
              }
              USE WHEEL_TRANS
            ]
            boundingObject Transform {
              translation 0 0 0.02
              rotation 1 0 0 1.5708
              children [
                DEF wheel1 Shape {
                  appearance PBRAppearance {
                    baseColor 0.8 0.8 0.8
                    transparency 0.12999999523162842
                    roughness 1
                    metalness 0
                    emissiveColor 0 1 0
                  }
                  geometry Cylinder {
                    height 0.02
                    radius 0.05
                  }
                }
              ]
            }
            physics Physics {
            }
          }
        }
      ]
      name "wheel 2"
      boundingObject USE DUMMY
      physics Physics {
      }
    }
    DEF SOLID3 Solid {
      rotation 0 1 0 4.18
      children [
        DEF WHEEL3 HingeJoint {
          jointParameters HingeJointParameters {
            position 17.40695256235233
            axis 0 0 1
            anchor 0 0 0.1
          }
          device [
            PositionSensor {
              name "encoder_right"
            }
            RotationalMotor {
              name "wheel3"
              maxVelocity 52.35
              maxTorque 0.49
            }
          ]
          endPoint Solid {
            translation 0 0 0.1
            rotation 0 0 1 4.844491387993065
            children [
              DEF sr1 HingeJoint {
                jointParameters HingeJointParameters {
                  position 42.24736456484447
                  anchor 0 0.05 0.02
                }
                endPoint Solid {
                  translation 0 0.05 0.02
                  rotation 1 0 0 4.548252721766948
                  children [
                    USE r1
                  ]
                  name "sr1"
                  boundingObject USE r1
                  physics Physics {
                    density -1
                    mass 0.1
                  }
                }
              }
              DEF sr2 HingeJoint {
                jointParameters HingeJointParameters {
                  position 206.33844079512582
                  axis 0.707107 0.707107 0
                  anchor -0.03535 0.03535 0.02
                }
                endPoint Solid {
                  translation -0.03535 0.03535 0.02
                  rotation 0.7071067811865475 0.7071067811865475 0 5.276510965379052
                  children [
                    USE r2
                  ]
                  name "sr2"
                  boundingObject USE r2
                  physics Physics {
                    density -1
                    mass 0.1
                  }
                }
              }
              DEF sr3 HingeJoint {
                jointParameters HingeJointParameters {
                  position 27.941457812888547
                  anchor 0 -0.05 0.02
                }
                endPoint Solid {
                  translation 0 -0.05 0.02
                  rotation 0.9999999999999999 0 0 2.8087165841702015
                  children [
                    USE r3
                  ]
                  name "sr3"
                  boundingObject USE r3
                  physics Physics {
                    density -1
                    mass 0.1
                  }
                }
              }
              DEF sr4 HingeJoint {
                jointParameters HingeJointParameters {
                  position 205.4532872845357
                  axis 0.707107 0.707107 0
                  anchor 0.03535 -0.03535 0.02
                }
                endPoint Solid {
                  translation 0.03535 -0.03535 0.02
                  rotation 0.7071067811865476 0.7071067811865476 0 4.391357454788923
                  children [
                    USE r4
                  ]
                  name "sr4"
                  boundingObject USE r4
                  physics Physics {
                    density -1
                    mass 0.1
                  }
                }
              }
              DEF sr5 HingeJoint {
                jointParameters HingeJointParameters {
                  position 248.09421224685428
                  axis 0 1 0
                  anchor -0.05 0 0.02
                }
                endPoint Solid {
                  translation -0.05 0 0.02
                  rotation 0 -1 0 3.2332000403291756
                  children [
                    USE r5
                  ]
                  name "sr5"
                  boundingObject USE r5
                  physics Physics {
                    density -1
                    mass 0.1
                  }
                }
              }
              DEF sr6 HingeJoint {
                jointParameters HingeJointParameters {
                  position 165.20895382966953
                  axis 0 1 0
                  anchor 0.05 0 0.02
                }
                endPoint Solid {
                  translation 0.05 0 0.02
                  rotation 0 1 0 1.846135843000277
                  children [
                    USE r6
                  ]
                  name "sr6"
                  boundingObject USE r6
                  physics Physics {
                    density -1
                    mass 0.1
                  }
                }
              }
              DEF sr7 HingeJoint {
                jointParameters HingeJointParameters {
                  position 298.0801112963609
                  axis -0.707107 0.707107 0
                  anchor -0.03535 -0.03535 0.02
                }
                endPoint Solid {
                  translation -0.03535 -0.03535 0.02
                  rotation 0.7071067811865475 -0.7071067811865475 0 3.5127834482592677
                  children [
                    USE r7
                  ]
                  name "sr7"
                  boundingObject USE r7
                  physics Physics {
                    density -1
                    mass 0.1
                  }
                }
              }
              DEF sr8 HingeJoint {
                jointParameters HingeJointParameters {
                  position 64.27969192205846
                  axis -0.707107 0.707107 0
                  anchor 0.03535 0.03535 0.02
                }
                endPoint Solid {
                  translation 0.03535 0.03535 0.02
                  rotation -0.7071067811865476 0.7071067811865476 0 1.4478388502625967
                  children [
                    USE r8
                  ]
                  name "sr8"
                  boundingObject USE r8
                  physics Physics {
                    density -1
                    mass 0.1
                  }
                }
              }
              USE WHEEL_TRANS
            ]
            boundingObject Transform {
              translation 0 0 0.02
              rotation 1 0 0 1.5708
              children [
                DEF wheel1 Shape {
                  appearance PBRAppearance {
                    baseColor 0.8 0.8 0.8
                    transparency 0.12999999523162842
                    roughness 1
                    metalness 0
                    emissiveColor 0 1 0
                  }
                  geometry Cylinder {
                    height 0.02
                    radius 0.05
                  }
                }
              ]
            }
            physics Physics {
            }
          }
        }
      ]
      name "wheel 3"
      boundingObject USE DUMMY
      physics Physics {
      }
    }
    DEF BODY_TRANS Transform {
      translation 0 0.03 0
      children [
        Shape {
          appearance PBRAppearance {
            baseColor 0.8 0 0
            roughness 1
            metalness 0
          }
          geometry Cylinder {
            height 0.15
            radius 0.1
            subdivision 18
          }
        }
      ]
    }
    DEF sensor_right DistanceSensor {
      translation -0.04 0.06999999999999999 -0.07
      rotation 0 -1 0 4.306784100359174
      scale 0.5 0.5 0.5
      children [
        Shape {
          geometry Box {
            size 0.1 0.1 0.1
          }
        }
      ]
      name "distance_sensor_right"
      lookupTable [
        0 0 0
        0.02 0 0
        5 1659 0
      ]
      resolution 0.3
    }
    DEF sensor_left DistanceSensor {
      translation -0.09 0.060000000000000005 0.01
      rotation 0 1 0 2.761799387
      scale 0.5 0.5 0.5
      children [
        Shape {
          geometry Box {
            size 0.1 0.1 0.1
          }
        }
      ]
      name "distance_sensor_left"
      lookupTable [
        0 0 0
        0.02 0 0
        5 1659 0
      ]
      resolution 0.3
    }
  ]
  boundingObject USE BODY_TRANS
  physics Physics {
  }
  controller "Robot"
}
Solid {
  translation -0.7188010838144959 0 -0.4150000022977181
  rotation 0 1 0 1.0471975479999998
  children [
    Shape {
      appearance RedBricks {
      }
      geometry DEF WALL Box {
        size 0.6 0.6 0.1
      }
    }
  ]
  boundingObject USE WALL
}
Solid {
  translation -0.6985938043353032 0 -1.4818881890409752
  rotation 0 -1 0 6.021385939359174
  children [
    Shape {
      appearance RedBricks {
      }
      geometry DEF WALL Box {
        size 0.6 0.6 0.1
      }
    }
  ]
  name "solid(1)"
  boundingObject USE WALL
}
Solid {
  translation -1.664519635795248 0 -1.223069163236432
  rotation 0 1 0 1.0471975096408255
  children [
    Shape {
      appearance RedBricks {
      }
      geometry DEF WALL Box {
        size 0.6 0.6 0.1
      }
    }
  ]
  name "solid(2)"
  boundingObject USE WALL
}
